Workbook
Name IQ_CH: 110000
Name IQ_CQ: 5000
Name IQ_CY: 10000
Name IQ_DAILY: 500000
Name IQ_FH: 100000
Name IQ_FQ: 500
Name IQ_FY: 1000
Name IQ_LTM: 2000
Name IQ_MONTH: 15000
Name IQ_NTM: 6000
Name IQ_WEEK: 50000
Name IQ_YTD: 3000

Sheet Cover Page
B24: Submitted by: Submitted to:
B25: Tolulope Oluwabunmi | F25: Hamza Abdurezak, PhD., FRM

Sheet Summary Table
A3: Financial Model
A4: SUMMARY RESULTS
A5: DCF VALUATION
A6: Scenarios | B6: Assumed Probablities | D6: Enterprise Values | E6: Equity Values | F6: Value Per Share | G6: Market Price
G7: 52 Week Range: 82.11 - 134.12
A8: Base Case | B8: 0.5 | D8: 389933.08 | E8: 371795.94 | F8: 87 | G8: Recommendation: | H8: HOLD
A9: Best Case | B9: 0.25 | D9: 666926.44 | E9: 648789.31 | F9: 152
A10: Worst Case | B10: 0.25 | D10: 259453.3 | E10: 241316.17 | F10: 57
A11: Expected Value | D11: =SUMPRODUCT(D8:D10,$B$8:$B$10) -> 426561.47 | E11: =SUMPRODUCT(E8:E10,$B$8:$B$10) -> 408424.34 | F11: =SUMPRODUCT(F8:F10,$B$8:$B$10) -> 95.75
A13: Multiple Based Valuation, Value per share
A14: Scenarios | B14: P/E Multiple | C14: EBITDA Multiple | D14: Revenue Multiple
A15: Base Case | B15: 72.299851 | C15: 43.227621 | D15: 27.447314
A16: Best Case | B16: 77.481582 | C16: 46.54049 | D16: 27.983655
A17: Worst Case | B17: 67.45752 | C17: 40.131741 | D17: 26.910974
A18: Expected Value | B18: =B15*$B8+B16*$B9+B17*$B10 -> 72.384701 | C18: =C15*$B8+C16*$B9+C17*$B10 -> 43.281868 | D18: =D15*$B8+D16*$B9+D17*$B10 -> 27.447314
A20: Trading Multiples ( The average of the top Comparables) | C20: ='Multiples Valuation'!F4 -> Trading Multiple of Netflix
A21: NTM TEV/Forward Total Revenue (Capital IQ) | B21: ='Multiples Valuation'!D5 -> 3.0377778 | C21: ='Multiples Valuation'!F5 -> 9.39
A22: NTM TEV/Forward EBITDA (Capital IQ) | B22: ='Multiples Valuation'!D6 -> 16.385556 | C22: ='Multiples Valuation'!F6 -> 28.14
A23: NTM Forward P/E (Capital IQ) | B23: ='Multiples Valuation'!D7 -> 34.172 | C23: ='Multiples Valuation'!F7 -> 32.59

Sheet Assumption Table
A1: NETFLIX
A2: MODEL ASSUMPTIONS
B4: GENERAL | L4: Capital Expenditure Assumptions, average of % Revenue
B5: - | C5: First year of forecast period in the model: | I5: 2025 | L5: ='Data Source Table'!A106 -> Land | V5: ='Data Source Table'!O106 -> 0.0024381894
B6: - | C6: =CONCATENATE("The model is a 5-year cash flow model discounted to Dec. 31, ",I5-1) -> The model is a 5-year cash flow model discounted to Dec. 31, 2024 | L6: ='Data Source Table'!A107 -> Building | V6: ='Data Source Table'!O107 -> 0.0043491351
L7: ='Data Source Table'!A108 -> Leasehold improvements | V7: ='Data Source Table'!O108 -> 0.027981543 | Y7: hohdas
L8: ='Data Source Table'!A109 -> Furniture and fixtures | V8: ='Data Source Table'!O109 -> 0.0043459584
B9: REVENUE GROWTH ASSUMPTIONS, based on historical arithmetic average | L9: ='Data Source Table'!A110 -> Information technology | V9: ='Data Source Table'!O110 -> 0.012372115
L10: ='Data Source Table'!A111 -> Corporate aircraft | V10: ='Data Source Table'!O111 -> 0.0034604452
B11: ='Data Source Table'!A82 -> Total Streaming Revenue | I11: ='Data Source Table'!O82 -> 0.14667351 | L11: ='Data Source Table'!A112 -> Machinery and Equipment | V11: ='Data Source Table'!O112 -> 0.00080405061
B12: DVD revenues | I12: ='Data Source Table'!O83 -> 0 | L12: ='Data Source Table'!A113 -> Capital work-in-progress | V12: ='Data Source Table'!O113 -> 0.009361249
B13: Operating Income | I13: ='Data Source Table'!O86 -> 0.35071882
L14: Depreciation Assumptions
B15: MEMBERSHIP GROWTH ASSUMPTIONS, based on historical arithmetic average | L15: Assumed Depreciation Method: | P15: Straight Line
L16: Asset | Q16: Useful Life
B17: ='Data Source Table'!A89 -> Paid net membership additions | I17: ='Data Source Table'!O89 -> 0.40359561 | L17: ='Data Source Table'!A106 -> Land | Q17: No Depreciation
B18: ='Data Source Table'!A90 -> Paid memberships at end of period | I18: ='Data Source Table'!O90 -> 0.127025 | L18: ='Data Source Table'!A107 -> Building | Q18: 30
B19: ='Data Source Table'!A91 -> Average paying memberships | I19: ='Data Source Table'!O91 -> 0.12837114 | L19: ='Data Source Table'!A108 -> Leasehold improvements | Q19: 15
B20: ='Data Source Table'!A92 -> Average monthly revenue per paying membership | I20: ='Data Source Table'!O92 -> 0.016128286 | L20: ='Data Source Table'!A109 -> Furniture and fixtures | Q20: 5
L21: ='Data Source Table'!A110 -> Information technology | Q21: 5
L22: ='Data Source Table'!A111 -> Corporate aircraft | Q22: 10
B23: PRICE GROWTH ASSUMPTIONS, based on historical arithmetic average | L23: ='Data Source Table'!A112 -> Machinery and Equipment | Q23: 5
L24: ='Data Source Table'!A113 -> Capital work-in-progress | Q24: No Depreciation
B25: ='Data Source Table'!A92 -> Average monthly revenue per paying membership | I25: ='Data Source Table'!O92 -> 0.016128286
L27: Long Term Debt Assumption
B28: ='Data Source Table'!A286 -> Interest and Invest. Income | I28: ='Data Source Table'!P286 -> 1.7543145 | L28: Beginning Debt Level as (2025), in $MM | Q28: ='Data Source Table'!I142 -> 14592.733
B29: ='Data Source Table'!A289 -> Currency Exchange Gains (Loss) | I29: -0.1 | L29: Long term Lease, Level | Q29: ='Data Source Table'!I143 -> 2004.95
B30: Operating Expenses growth rate, historical arithmatic avearage | L30: Long Term Debt Growth Rate | Q30: 0.05
B31: ='Data Source Table'!A97 -> Sales and Marketing | I31: ='Data Source Table'!O97 -> 0.024910761 | L31: Interest rate on long term debt | Q31: ='Capital Structure'!F19 -> 0.045416581
B32: ='Data Source Table'!A98 -> Technology and development | I32: ='Data Source Table'!O98 -> 0.13988386 | L32: Long Term Debt Repayment During forecat period | Q32: 0
B33: ='Data Source Table'!A100 -> Interest Expense | I33: ='Data Source Table'!O100 -> 0.032784592
B34: ='Data Source Table'!A99 -> General and administrative | I34: ='Data Source Table'!O99 -> 0.13593905 | L34: Tax rate assumed in this model | Q34: 0.25
B35: ='Data Source Table'!A94 -> Cost of Revenues | I35: ='Data Source Table'!O94 -> 0.11282903 | L35: Dividend Payout Ratio ( Average of 4 years) | Q35: 0
B37: Working Capital Assumptions
B38: Assumed to change as % of revenue based on historical arithmetic average | L38: Long Term Commitment Ex Operating Lease
B39: ='Data Source Table'!A118 -> Accounts Receivable | I39: ='Data Source Table'!O118 -> 0.03104033 | Q39: 2024 | R39: =Q39+1 -> 2025 | S39: =R39+1 -> 2026 | T39: =S39+1 -> 2027 | U39: After 5 years due
B40: ='Data Source Table'!A119 -> Other Receivables | I40: ='Data Source Table'!O119 -> 0.017371795 | L40: Long term debt including capital lease payment schedule, in $MM | Q40: {=TRANSPOSE('Data Source Table'!B148:B153)} -> 1953.2 | R40: - | S40: - | T40: - | U40: 1953.2 | V40: 13629.6
B41: ='Data Source Table'!A120 -> Prepaid Exp. | I41: ='Data Source Table'!O120 -> 0.010928953 | L41: Of Which Capital Leasse, in $MM
B42: ='Data Source Table'!A121 -> Other Current Assets | I42: ='Data Source Table'!O121 -> 0.028582494 | L42: Other Contractual Obligation ( Purchase), in $MM | Q42: {=TRANSPOSE('Data Source Table'!B165:B170)} -> 11424.7 | R42: - | S42: - | T42: - | U42: 11424.7 | V42: 11824.2
B44: ='Data Source Table'!A123 -> Accounts Payable | I44: ='Data Source Table'!O123 -> 0.02418578
...

Sheet The Model
A2: Revenue Schedule
C4: =D4-1 -> 2022 | D4: =E4-1 -> 2023 | E4: =F4-1 -> 2024 | F4: ='Assumption Table'!I5 -> 2025 | G4: =F4+1 -> 2026 | H4: =G4+1 -> 2027 | I4: =H4+1 -> 2028 | J4: =I4+1 -> 2029
B6: ='Data Source Table'!A82 -> Total Streaming Revenue | C6: ='Data Source Table'!E82 -> 31469852 | D6: ='Data Source Table'!F82 -> 33640458 | E6: ='Data Source Table'!G82 -> 39000966 | F6: =E6*(1+'Scenario Table'!H10) -> 44721374 | G6: =F6*(1+'Scenario Table'!I10) -> 51280815 | H6: =G6*(1+'Scenario Table'!J10) -> 58802352 | I6: =H6*(1+'Scenario Table'!K10) -> 67427099 | J6: =I6*(1+'Scenario Table'!L10) -> 77316868
B7: ='Data Source Table'!A83 -> DVD REVENUE | C7: ='Data Source Table'!E83 -> 145698 | D7: ='Data Source Table'!F83 -> 82839 | E7: ='Data Source Table'!G83 -> 0 | F7: =E7*(1+'Assumption Table'!$I$12) -> 0 | G7: =F7*(1+'Assumption Table'!$I$12) -> 0 | H7: =G7*(1+'Assumption Table'!$I$12) -> 0 | I7: =H7*(1+'Assumption Table'!$I$12) -> 0 | J7: =I7*(1+'Assumption Table'!$I$12) -> 0
B8: ='Data Source Table'!A84 -> Total Revenue | C8: ='Data Source Table'!E84 -> 31615550 | D8: ='Data Source Table'!F84 -> 33723297 | E8: ='Data Source Table'!G84 -> 39000966 | F8: =F6+F7 -> 44721374 | G8: =G6+G7 -> 51280815 | H8: =H6+H7 -> 58802352 | I8: =I6+I7 -> 67427099 | J8: =J6+J7 -> 77316868
B10: ='Data Source Table'!A86 -> Operating Income | C10: ='Data Source Table'!E86 -> 5632831 | D10: ='Data Source Table'!F86 -> 6954003 | E10: ='Data Source Table'!G86 -> 10417614 | F10: =E10*(1+'Assumption Table'!$I$13) -> 14071267 | G10: =F10*(1+'Assumption Table'!$I$13) -> 19006326 | H10: =G10*(1+'Assumption Table'!$I$13) -> 25672202 | I10: =H10*(1+'Assumption Table'!$I$13) -> 34675926 | J10: =I10*(1+'Assumption Table'!$I$13) -> 46837426
B11: ='Data Source Table'!A87 -> Operating margin | C11: ='Data Source Table'!E87 -> 0.18 | D11: ='Data Source Table'!F87 -> 0.21 | E11: ='Data Source Table'!G87 -> 0.27 | F11: =F10/F8 -> 0.314643 | G11: =G10/G8 -> 0.37063228 | H11: =H10/H8 -> 0.43658461 | I11: =I10/I8 -> 0.51427284 | J11: =J10/J8 -> 0.60578535
B13: ='Data Source Table'!A89 -> Paid net membership additions | C13: ='Data Source Table'!E89 -> 8903 | D13: ='Data Source Table'!F89 -> 29529 | E13: ='Data Source Table'!G89 -> 41350 | F13: =E13*(1+'Scenario Table'!H25) -> 58038.679 | G13: =F13*(1+'Scenario Table'!I25) -> 81462.834 | H13: =G13*(1+'Scenario Table'!J25) -> 114340.88 | I13: =H13*(1+'Scenario Table'!K25) -> 160488.35 | J13: =I13*(1+'Scenario Table'!L25) -> 225260.75
B14: ='Data Source Table'!A90 -> Paid memberships at end of period | C14: ='Data Source Table'!E90 -> 230747 | D14: ='Data Source Table'!F90 -> 260276 | E14: ='Data Source Table'!G90 -> 301626 | F14: =E14*(1+'Assumption Table'!$I$18) -> 339940.04 | G14: =F14*(1+'Assumption Table'!$I$18) -> 383120.93 | H14: =G14*(1+'Assumption Table'!$I$18) -> 431786.86 | I14: =H14*(1+'Assumption Table'!$I$18) -> 486634.59 | J14: =I14*(1+'Assumption Table'!$I$18) -> 548449.35
B15: ='Data Source Table'!A91 -> Average paying memberships | C15: ='Data Source Table'!E91 -> 222924 | D15: ='Data Source Table'!F91 -> 240889 | E15: ='Data Source Table'!G91 -> 277730 | F15: =E15*(1+'Scenario Table'!H18) -> 313382.52 | G15: =F15*(1+'Scenario Table'!I18) -> 353611.79 | H15: =G15*(1+'Scenario Table'!J18) -> 399005.34 | I15: =H15*(1+'Scenario Table'!K18) -> 450226.11 | J15: =I15*(1+'Scenario Table'!L18) -> 508022.16
B16: ='Data Source Table'!A92 -> Average monthly revenue per paying membership | C16: ='Data Source Table'!E92 -> 11.76 | D16: ='Data Source Table'!F92 -> 11.64 | E16: ='Data Source Table'!G92 -> 11.7 | F16: =E16*(1+'Assumption Table'!$I$20) -> 11.888701 | G16: =F16*(1+'Assumption Table'!$I$20) -> 12.080445 | H16: =G16*(1+'Assumption Table'!$I$20) -> 12.275282 | I16: =H16*(1+'Assumption Table'!$I$20) -> 12.473261 | J16: =I16*(1+'Assumption Table'!$I$20) -> 12.674434
B18: Total Revenue | C18: =C8 -> 31615550 | D18: =D8 -> 33723297 | E18: =E8 -> 39000966 | F18: =F8 -> 44721374 | G18: =G8 -> 51280815 | H18: =H8 -> 58802352 | I18: =I8 -> 67427099 | J18: =J8 -> 77316868
B19: ='Data Source Table'!A94 -> Cost of Revenues | C19: ='Data Source Table'!E94 -> 19168285 | D19: ='Data Source Table'!F94 -> 19715368 | E19: ='Data Source Table'!G94 -> 21038464 | F19: =E19*(1+'Assumption Table'!$I$35) -> 23412213 | G19: =F19*(1+'Assumption Table'!$I$35) -> 26053791 | H19: =G19*(1+'Assumption Table'!$I$35) -> 28993415 | I19: =H19*(1+'Assumption Table'!$I$35) -> 32264713 | J19: =I19*(1+'Assumption Table'!$I$35) -> 35905110
B21: Consolidated Operation Cost Schedule
C23: =C4 -> 2022 | D23: =D4 -> 2023 | E23: =E4 -> 2024 | F23: =F4 -> 2025 | G23: =G4 -> 2026 | H23: =H4 -> 2027 | I23: =I4 -> 2028 | J23: =J4 -> 2029
B24: In $MM
B25: ='Data Source Table'!A97 -> Sales and Marketing | C25: ='Data Source Table'!E97 -> 2530502 | D25: ='Data Source Table'!F97 -> 2657883 | E25: ='Data Source Table'!G97 -> 2917554 | F25: =E25*(1+'Scenario Table'!H48) -> 2990232.5 | G25: =F25*(1+'Scenario Table'!I48) -> 3064721.5 | H25: =G25*(1+'Scenario Table'!J48) -> 3141066 | I25: =H25*(1+'Scenario Table'!K48) -> 3219312.3 | J25: =I25*(1+'Scenario Table'!L48) -> 3299507.9
B26: ='Data Source Table'!A98 -> Technology and development | C26: ='Data Source Table'!E98 -> 2711041 | D26: ='Data Source Table'!F98 -> 2675758 | E26: ='Data Source Table'!G98 -> 2925295 | F26: =E26*(1+'Scenario Table'!H34) -> 3334496.5 | G26: =F26*(1+'Scenario Table'!I34) -> 3800938.8 | H26: =G26*(1+'Scenario Table'!J34) -> 4332628.7 | I26: =H26*(1+'Scenario Table'!K34) -> 4938693.6 | J26: =I26*(1+'Scenario Table'!L34) -> 5629537
B27: ='Data Source Table'!A99 -> General and administrative | C27: ='Data Source Table'!E99 -> 1572891 | D27: ='Data Source Table'!F99 -> 1720285 | E27: ='Data Source Table'!G99 -> 1702039 | F27: =E27*(1+'Scenario Table'!H41) -> 1933412.6 | G27: =F27*(1+'Scenario Table'!I41) -> 2196238.9 | H27: =G27*(1+'Scenario Table'!J41) -> 2494793.5 | I27: =H27*(1+'Scenario Table'!K41) -> 2833933.4 | J27: =I27*(1+'Scenario Table'!L41) -> 3219175.6
B29: Operating Leases, as planned, in $MM | F29: ='Assumption Table'!Q47 -> 505201 | G29: ='Assumption Table'!R47 -> 477256 | H29: ='Assumption Table'!S47 -> 415983 | I29: ='Assumption Table'!T47 -> 345912 | J29: ='Assumption Table'!U47 -> 276109
B31: Total Operation Expense | C31: =SUM(C25:C29) -> 6814434 | D31: =SUM(D25:D29) -> 7053926 | E31: =SUM(E25:E29) -> 7544888 | F31: =SUM(F25:F29) -> 8763342.6 | G31: =SUM(G25:G29) -> 9539155.1 | H31: =SUM(H25:H29) -> 10384471 | I31: =SUM(I25:I29) -> 11337851 | J31: =SUM(J25:J29) -> 12424329
B36: Capital Expenditure Projections
C38: =C23 -> 2022 | D38: =D23 -> 2023 | E38: =E23 -> 2024 | F38: =F23 -> 2025 | G38: =G23 -> 2026 | H38: =H23 -> 2027 | I38: =I23 -> 2028 | J38: =J23 -> 2029
B39: In $MM
B40: Land | C40: ='Data Source Table'!E106 -> 85005 | D40: ='Data Source Table'!F106 -> 85000 | E40: ='Data Source Table'!G106 -> 85000 | F40: ='Assumption Table'!$V$5*'The Model'!F18 -> 109039.18 | G40: ='Assumption Table'!$V$5*'The Model'!G18 -> 125032.34 | H40: ='Assumption Table'!$V$5*'The Model'!H18 -> 143371.27 | I40: ='Assumption Table'!$V$5*'The Model'!I18 -> 164400.04 | J40: ='Assumption Table'!$V$5*'The Model'!J18 -> 188513.17
B41: Capex | F41: =(F40-E40)/1000 -> 24.03918 | G41: =(G40-F40)/1000 -> 15.993159 | H41: =(H40-G40)/1000 -> 18.338931 | I41: =(I40-H40)/1000 -> 21.028767 | J41: =(J40-I40)/1000 -> 24.11313
B42: Building | C42: ='Data Source Table'!E107 -> 52106 | D42: ='Data Source Table'!F107 -> 154165 | E42: ='Data Source Table'!G107 -> 475684 | F42: ='Assumption Table'!$V$6*'The Model'!F18 -> 194499.3 | G42: ='Assumption Table'!$V$6*'The Model'!G18 -> 223027.19 | H42: ='Assumption Table'!$V$6*'The Model'!H18 -> 255739.37 | I42: ='Assumption Table'!$V$6*'The Model'!I18 -> 293249.57 | J42: ='Assumption Table'!$V$6*'The Model'!J18 -> 336261.51
B43: Capex | F43: =(F42-E42)/1000 -> -281.1847 | G43: =(G42-F42)/1000 -> 28.527894 | H43: =(H42-G42)/1000 -> 32.71218 | I43: =(I42-H42)/1000 -> 37.510191 | J43: =(J42-I42)/1000 -> 43.011942
B44: Leasehold improvements | C44: ='Data Source Table'!E108 -> 1040570 | D44: ='Data Source Table'!F108 -> 1032492 | E44: ='Data Source Table'!G108 -> 1026593 | F44: ='Assumption Table'!$V$7*'The Model'!F18 -> 1251373.1 | G44: ='Assumption Table'!$V$7*'The Model'!G18 -> 1434916.3 | H44: ='Assumption Table'!$V$7*'The Model'!H18 -> 1645380.5 | I44: ='Assumption Table'!$V$7*'The Model'!I18 -> 1886714.3 | J44: ='Assumption Table'!$V$7*'The Model'!J18 -> 2163445.3
B45: Capex | F45: =(F44-E44)/1000 -> 224.78005 | G45: =(G44-F44)/1000 -> 183.54327 | H45: =(H44-G44)/1000 -> 210.46421 | I45: =(I44-H44)/1000 -> 241.33373 | J45: =(J44-I44)/1000 -> 276.73099
B46: Furniture and fixtures | C46: ='Data Source Table'!E109 -> 153682 | D46: ='Data Source Table'!F109 -> 144737 | E46: ='Data Source Table'!G109 -> 134987 | F46: ='Assumption Table'!$V$8*'The Model'!F18 -> 194357.23 | G46: ='Assumption Table'!$V$8*'The Model'!G18 -> 222864.29 | H46: ='Assumption Table'!$V$8*'The Model'!H18 -> 255552.58 | I46: ='Assumption Table'!$V$8*'The Model'!I18 -> 293035.37 | J46: ='Assumption Table'!$V$8*'The Model'!J18 -> 336015.9
B47: Capex | F47: =(F46-E46)/1000 -> 59.370234 | G47: =(G46-F46)/1000 -> 28.507057 | H47: =(H46-G46)/1000 -> 32.688287 | I47: =(I46-H46)/1000 -> 37.482792 | J47: =(J46-I46)/1000 -> 42.980525
B48: Information technology | C48: ='Data Source Table'!E110 -> 442681 | D48: ='Data Source Table'!F110 -> 414092 | E48: ='Data Source Table'!G110 -> 446419 | F48: ='Assumption Table'!$V$9*'The Model'!F18 -> 553297.99 | G48: ='Assumption Table'!$V$9*'The Model'!G18 -> 634452.15 | H48: ='Assumption Table'!$V$9*'The Model'!H18 -> 727509.47 | I48: ='Assumption Table'!$V$9*'The Model'!I18 -> 834215.83 | J48: ='Assumption Table'!$V$9*'The Model'!J18 -> 956573.19
B49: Capex | F49: =(F48-E48)/1000 -> 106.87899 | G49: =(G48-F48)/1000 -> 81.154156 | H49: =(H48-G48)/1000 -> 93.05732 | I49: =(I48-H48)/1000 -> 106.70636 | J49: =(J48-I48)/1000 -> 122.35736
B50: Corporate aircraft | C50: ='Data Source Table'!E111 -> 115578 | D50: ='Data Source Table'!F111 -> 99175 | E50: ='Data Source Table'!G111 -> 99175 | F50: ='Assumption Table'!$V$10*'The Model'!F18 -> 154755.87 | G50: ='Assumption Table'!$V$10*'The Model'!G18 -> 177454.45 | H50: ='Assumption Table'!$V$10*'The Model'!H18 -> 203482.32 | I50: ='Assumption Table'!$V$10*'The Model'!I18 -> 233327.78 | J50: ='Assumption Table'!$V$10*'The Model'!J18 -> 267550.79
B51: Capex | F51: =(F50-E50)/1000 -> 55.580868 | G51: =(G50-F50)/1000 -> 22.698586 | H51: =(H50-G50)/1000 -> 26.027867 | I51: =(I50-H50)/1000 -> 29.845465 | J51: =(J50-I50)/1000 -> 34.223004
B52: Machinery and Equipment | C52: ='Data Source Table'!E112 -> 26821 | D52: ='Data Source Table'!F112 -> 10334 | E52: ='Data Source Table'!G112 -> 15135 | F52: ='Assumption Table'!$V$11*'The Model'!F18 -> 35958.249 | G52: ='Assumption Table'!$V$11*'The Model'!G18 -> 41232.371 | H52: ='Assumption Table'!$V$11*'The Model'!H18 -> 47280.067 | I52: ='Assumption Table'!$V$11*'The Model'!I18 -> 54214.8 | J52: ='Assumption Table'!$V$11*'The Model'!J18 -> 62166.675
B53: Capex | F53: =(F52-E52)/1000 -> 20.823249 | G53: =(G52-F52)/1000 -> 5.2741224 | H53: =(H52-G52)/1000 -> 6.0476964 | I53: =(I52-H52)/1000 -> 6.9347332 | J53: =(J52-I52)/1000 -> 7.9518748
B54: Capital work-in-progress | C54: ='Data Source Table'!E113 -> 235555 | D54: ='Data Source Table'!F113 -> 406492 | E54: ='Data Source Table'!G113 -> 228300 | F54: ='Assumption Table'!$V$12*'The Model'!F18 -> 418647.92 | G54: ='Assumption Table'!$V$12*'The Model'!G18 -> 480052.48 | H54: ='Assumption Table'!$V$12*'The Model'!H18 -> 550463.46 | I54: ='Assumption Table'!$V$12*'The Model'!I18 -> 631201.87 | J54: ='Assumption Table'!$V$12*'The Model'!J18 -> 723782.46
B55: Capex | F55: =(F54-E54)/1000 -> 190.34792 | G55: =(G54-F54)/1000 -> 61.404558 | H55: =(H54-G54)/1000 -> 70.41098 | I55: =(I54-H54)/1000 -> 80.738405 | J55: =(J54-I54)/1000 -> 92.58059
...

Sheet Scenario Table
A1: {=_xlfn.IFS(D4="Base Case",1,D4="Best Case",2,D4="Worst Case",3)} -> 1
C4: Switch: | D4: Base Case
H6: ='The Model'!F4 -> 2025 | I6: ='The Model'!G4 -> 2026 | J6: ='The Model'!H4 -> 2027 | K6: ='The Model'!I4 -> 2028 | L6: ='The Model'!J4 -> 2029
B8: ='Assumption Table'!B56 -> Key Revenue Risk Variable
C9: ='Assumption Table'!B57 -> Total Streaming Revenue
E10: Currently Running | H10: =CHOOSE($A$1,H12,H13,H14) -> 0.14667351 | I10: =CHOOSE($A$1,I12,I13,I14) -> 0.14667351 | J10: =CHOOSE($A$1,J12,J13,J14) -> 0.14667351 | K10: =CHOOSE($A$1,K12,K13,K14) -> 0.14667351 | L10: =CHOOSE($A$1,L12,L13,L14) -> 0.14667351
E12: Base Case | H12: ='Assumption Table'!$I$11 -> 0.14667351 | I12: ='Assumption Table'!$I$11 -> 0.14667351 | J12: ='Assumption Table'!$I$11 -> 0.14667351 | K12: ='Assumption Table'!$I$11 -> 0.14667351 | L12: ='Assumption Table'!$I$11 -> 0.14667351
E13: Best Case | H13: =$H$12+'Assumption Table'!$I$58 -> 0.16667351 | I13: =$H$12+'Assumption Table'!$I$58 -> 0.16667351 | J13: =$H$12+'Assumption Table'!$I$58 -> 0.16667351 | K13: =$H$12+'Assumption Table'!$I$58 -> 0.16667351 | L13: =$H$12+'Assumption Table'!$I$58 -> 0.16667351
E14: Worst Case | H14: =$H$12+'Assumption Table'!$I$59 -> 0.12667351 | I14: =$H$12+'Assumption Table'!$I$59 -> 0.12667351 | J14: =$H$12+'Assumption Table'!$I$59 -> 0.12667351 | K14: =$H$12+'Assumption Table'!$I$59 -> 0.12667351 | L14: =$H$12+'Assumption Table'!$I$59 -> 0.12667351
C17: ='Assumption Table'!B60 -> Average Paying Membership
E18: Currently Running | H18: =CHOOSE($A$1,H20,H21,H22) -> 0.12837114 | I18: =CHOOSE($A$1,I20,I21,I22) -> 0.12837114 | J18: =CHOOSE($A$1,J20,J21,J22) -> 0.12837114 | K18: =CHOOSE($A$1,K20,K21,K22) -> 0.12837114 | L18: =CHOOSE($A$1,L20,L21,L22) -> 0.12837114
E20: Base Case | H20: ='Assumption Table'!I19 -> 0.12837114 | I20: =H20 -> 0.12837114 | J20: =I20 -> 0.12837114 | K20: =J20 -> 0.12837114 | L20: =K20 -> 0.12837114
E21: Best Case | H21: =H20+'Assumption Table'!$I$61 -> 0.13837114 | I21: =I20+'Assumption Table'!$I$61 -> 0.13837114 | J21: =J20+'Assumption Table'!$I$61 -> 0.13837114 | K21: =K20+'Assumption Table'!$I$61 -> 0.13837114 | L21: =L20+'Assumption Table'!$I$61 -> 0.13837114
E22: Worst Case | H22: =$H$20+'Assumption Table'!$I$62 -> 0.12337114 | I22: =$H$20+'Assumption Table'!$I$62 -> 0.12337114 | J22: =$H$20+'Assumption Table'!$I$62 -> 0.12337114 | K22: =$H$20+'Assumption Table'!$I$62 -> 0.12337114 | L22: =$H$20+'Assumption Table'!$I$62 -> 0.12337114
C24: ='Assumption Table'!B63 -> Paid net membership additions
E25: Currently Running | H25: =CHOOSE($A$1,H27,H28,H29) -> 0.40359561 | I25: =CHOOSE($A$1,I27,I28,I29) -> 0.40359561 | J25: =CHOOSE($A$1,J27,J28,J29) -> 0.40359561 | K25: =CHOOSE($A$1,K27,K28,K29) -> 0.40359561 | L25: =CHOOSE($A$1,L27,L28,L29) -> 0.40359561
E27: Base Case | H27: ='Assumption Table'!I17 -> 0.40359561 | I27: =H27 -> 0.40359561 | J27: =I27 -> 0.40359561 | K27: =J27 -> 0.40359561 | L27: =K27 -> 0.40359561
E28: Best Case | H28: ='Scenario Table'!H27+'Assumption Table'!$I$64 -> 0.43359561 | I28: ='Scenario Table'!I27+'Assumption Table'!$I$64 -> 0.43359561 | J28: ='Scenario Table'!J27+'Assumption Table'!$I$64 -> 0.43359561 | K28: ='Scenario Table'!K27+'Assumption Table'!$I$64 -> 0.43359561 | L28: ='Scenario Table'!L27+'Assumption Table'!$I$64 -> 0.43359561
E29: Worst Case | H29: =H27+'Assumption Table'!$I$65 -> 0.37359561 | I29: =I27+'Assumption Table'!$I$65 -> 0.37359561 | J29: =J27+'Assumption Table'!$I$65 -> 0.37359561 | K29: =K27+'Assumption Table'!$I$65 -> 0.37359561 | L29: =L27+'Assumption Table'!$I$65 -> 0.37359561
B32: ='Assumption Table'!B67 -> Key Operating Expense Risky Variables
C33: ='Assumption Table'!B68 -> Technology and development
E34: Currently Running | H34: =CHOOSE($A$1,H36,H37,H38) -> 0.13988386 | I34: =CHOOSE($A$1,I36,I37,I38) -> 0.13988386 | J34: =CHOOSE($A$1,J36,J37,J38) -> 0.13988386 | K34: =CHOOSE($A$1,K36,K37,K38) -> 0.13988386 | L34: =CHOOSE($A$1,L36,L37,L38) -> 0.13988386
E36: Base Case | H36: ='Assumption Table'!$I$32 -> 0.13988386 | I36: ='Assumption Table'!$I$32 -> 0.13988386 | J36: ='Assumption Table'!$I$32 -> 0.13988386 | K36: ='Assumption Table'!$I$32 -> 0.13988386 | L36: ='Assumption Table'!$I$32 -> 0.13988386
E37: Best Case | H37: =H36+'Assumption Table'!$I$69 -> 0.11988386 | I37: =I36+'Assumption Table'!$I$69 -> 0.11988386 | J37: =J36+'Assumption Table'!$I$69 -> 0.11988386 | K37: =K36+'Assumption Table'!$I$69 -> 0.11988386 | L37: =L36+'Assumption Table'!$I$69 -> 0.11988386
E38: Worst Case | H38: =H36+'Assumption Table'!$J$70 -> 0.13988386 | I38: =I36+'Assumption Table'!$J$70 -> 0.13988386 | J38: =J36+'Assumption Table'!$J$70 -> 0.13988386 | K38: =K36+'Assumption Table'!$J$70 -> 0.13988386 | L38: =L36+'Assumption Table'!$J$70 -> 0.13988386
C40: ='Assumption Table'!B71 -> General and administrative
E41: Currently Running | H41: =CHOOSE($A$1,H43,H44,H45) -> 0.13593905 | I41: =CHOOSE($A$1,I43,I44,I45) -> 0.13593905 | J41: =CHOOSE($A$1,J43,J44,J45) -> 0.13593905 | K41: =CHOOSE($A$1,K43,K44,K45) -> 0.13593905 | L41: =CHOOSE($A$1,L43,L44,L45) -> 0.13593905
E43: Base Case | H43: ='Assumption Table'!$I$34 -> 0.13593905 | I43: ='Assumption Table'!$I$34 -> 0.13593905 | J43: ='Assumption Table'!$I$34 -> 0.13593905 | K43: ='Assumption Table'!$I$34 -> 0.13593905 | L43: ='Assumption Table'!$I$34 -> 0.13593905
E44: Best Case | H44: =H43+'Assumption Table'!$I$72 -> 0.12093905 | I44: =I43+'Assumption Table'!$I$72 -> 0.12093905 | J44: =J43+'Assumption Table'!$I$72 -> 0.12093905 | K44: =K43+'Assumption Table'!$I$72 -> 0.12093905 | L44: =L43+'Assumption Table'!$I$72 -> 0.12093905
E45: Worst Case | H45: =H43+'Assumption Table'!$I$73 -> 0.15093905 | I45: =I43+'Assumption Table'!$I$73 -> 0.15093905 | J45: =J43+'Assumption Table'!$I$73 -> 0.15093905 | K45: =K43+'Assumption Table'!$I$73 -> 0.15093905 | L45: =L43+'Assumption Table'!$I$73 -> 0.15093905
C47: ='Assumption Table'!B74 -> Sales and Marketing
E48: Currently Running | H48: =CHOOSE($A$1,H50,H51,H52) -> 0.024910761 | I48: =CHOOSE($A$1,I50,I51,I52) -> 0.024910761 | J48: =CHOOSE($A$1,J50,J51,J52) -> 0.024910761 | K48: =CHOOSE($A$1,K50,K51,K52) -> 0.024910761 | L48: =CHOOSE($A$1,L50,L51,L52) -> 0.024910761
E50: Base Case | H50: ='Assumption Table'!$I$31 -> 0.024910761 | I50: ='Assumption Table'!$I$31 -> 0.024910761 | J50: ='Assumption Table'!$I$31 -> 0.024910761 | K50: ='Assumption Table'!$I$31 -> 0.024910761 | L50: ='Assumption Table'!$I$31 -> 0.024910761
E51: Best Case | H51: =H50+'Assumption Table'!$I$75 -> 0.014910761 | I51: =I50+'Assumption Table'!$I$75 -> 0.014910761 | J51: =J50+'Assumption Table'!$I$75 -> 0.014910761 | K51: =K50+'Assumption Table'!$I$75 -> 0.014910761 | L51: =L50+'Assumption Table'!$I$75 -> 0.014910761
E52: Worst Case | H52: =H50+'Assumption Table'!$I$76 -> 0.034910761 | I52: =I50+'Assumption Table'!$I$76 -> 0.034910761 | J52: =J50+'Assumption Table'!$I$76 -> 0.034910761 | K52: =K50+'Assumption Table'!$I$76 -> 0.034910761 | L52: =L50+'Assumption Table'!$I$76 -> 0.034910761
C54: ='Assumption Table'!B78 -> Terminal Value Growth
E55: Currently Running | H55: =CHOOSE($A$1,H57,H58,H59) -> 0.04 | I55: =CHOOSE($A$1,I57,I58,I59) -> 0.04 | J55: =CHOOSE($A$1,J57,J58,J59) -> 0.04 | K55: =CHOOSE($A$1,K57,K58,K59) -> 0.04 | L55: =CHOOSE($A$1,L57,L58,L59) -> 0.04
E57: Base Case | H57: ='Assumption Table'!$Q$69 -> 0.04 | I57: ='Assumption Table'!$Q$69 -> 0.04 | J57: ='Assumption Table'!$Q$69 -> 0.04 | K57: ='Assumption Table'!$Q$69 -> 0.04 | L57: ='Assumption Table'!$Q$69 -> 0.04
E58: Best Case | H58: =H57+'Assumption Table'!$I$79 -> 0.06 | I58: =I57+'Assumption Table'!$I$79 -> 0.06 | J58: =J57+'Assumption Table'!$I$79 -> 0.06 | K58: =K57+'Assumption Table'!$I$79 -> 0.06 | L58: =L57+'Assumption Table'!$I$79 -> 0.06
E59: Worst Case | H59: =H57+'Assumption Table'!$I$80 -> 0.02 | I59: =I57+'Assumption Table'!$I$80 -> 0.02 | J59: =J57+'Assumption Table'!$I$80 -> 0.02 | K59: =K57+'Assumption Table'!$I$80 -> 0.02 | L59: =L57+'Assumption Table'!$I$80 -> 0.02
...

Sheet Multiples Valuation
D2: ="Currently Running: "&'Scenario Table'!D4 -> Currently Running: Base Case
C4: Trading Multiples ( The average of the top Comparables) | F4: ='Assumption Table'!L76 -> Trading Multiple of Netflix
C5: NTM TEV/Forward Total Revenue (Capital IQ) | D5: ='Assumption Table'!R72 -> 3.0377778 | F5: ='Assumption Table'!R77 -> 9.39
C6: NTM TEV/Forward EBITDA (Capital IQ) | D6: ='Assumption Table'!R73 -> 16.385556 | F6: ='Assumption Table'!R78 -> 28.14
C7: NTM Forward P/E (Capital IQ) | D7: ='Assumption Table'!R74 -> 34.172 | F7: ='Assumption Table'!R79 -> 32.59
C11: Netflix NTM data
C12: UPS In MM $, except EPS | D12: 2025
C13: Forward Total Revenue | D13: ='The Model'!F184 -> 44721.374
C14: Forward EBITDA | D14: ='The Model'!F196+'The Model'!F192 -> 12545.818
C15: Forward Net Income | D15: ='DCF Valuation Table'!F8 -> 9347.335
C16: Number of Shares outstanding (MM) | D16: ='DCF Valuation Table'!E28 -> 4261.515
C17: Forward EPS | D17: =D15/D16 -> 2.19343
C20: Total Enterprise Value, based on Revenue Multiple | D20: =D13*D5 -> 135853.6
C21: Total Debt | D21: ='The Model'!F151 -> 14592.733
C22: Total Equity | D22: =D20-D21 -> 121260.86
C23: Equity per share | D23: =D22/D16 -> 28.454872
C25: Total Enterprise Value, based on EBITDA Multiple | D25: =D14*D6 -> 205570.2
C26: Total Debt | D26: =D21 -> 14592.733
C27: Total Equity | D27: =D25-D26 -> 190977.47
C28: Equity per share | D28: =D27/D16 -> 44.814455
C30: Equity Value, based on PE Multiple | D30: =D17*D7 -> 74.953892

Sheet DCF Valuation Table
B2: Cost of Equity | C2: ='Scenario Table'!H63 -> 0.14433554 | F2: ="Currently Running: "&'Scenario Table'!D4 -> Currently Running: Base Case
B3: Cost of Debt | C3: ='Scenario Table'!H70 -> 0.045416581
B4: WACC | C4: ='Assumption Table'!S64 -> 0.14007181
B5: Sustainable long term growth rate | C5: ='Scenario Table'!H55 -> 0.04
E6: =F6-1 -> 2024 | F6: ='The Model'!F4 -> 2025 | G6: =F6+1 -> 2026 | H6: 2027 | I6: =H6+1 -> 2028 | J6: =I6+1 -> 2029
D7: FCF to Equity
D8: Net Income | F8: ='The Model'!F206 -> 9347.335 | G8: ='The Model'!G206 -> 12745.64 | H8: ='The Model'!H206 -> 18457.617 | I8: ='The Model'!I206 -> 29813.922 | J8: ='The Model'!J206 -> 55920.478
D9: Depreciation | F9: ='The Model'!F192 -> 213.52137 | G9: ='The Model'!G192 -> 213.56995 | H9: ='The Model'!H192 -> 213.6084 | I9: ='The Model'!I192 -> 213.65248 | J9: ='The Model'!J192 -> 213.70303
D10: CAPEX | F10: ='The Model'!F277 -> -1915.1586 | G10: ='The Model'!G277 -> 213.53285 | H10: ='The Model'!H277 -> 276.13907 | I10: ='The Model'!I277 -> 347.92797 | J10: ='The Model'!J277 -> 430.24639
D11: Changes in working capital | F11: ='The Model'!F179 -> -492.67747 | G11: ='The Model'!G179 -> 271.67197 | H11: ='The Model'!H179 -> 311.51905 | I11: ='The Model'!I179 -> 357.21064 | J11: ='The Model'!J179 -> 409.60398
B12: Total Debt- Cash | D12: Net Debt | F12: ='The Model'!F243-'The Model'!F214 -> -8512.5762 | G12: ='The Model'!G243-'The Model'!G214 -> -22321.391 | H12: ='The Model'!H243-'The Model'!H214 -> -41966.835 | I12: ='The Model'!I243-'The Model'!I214 -> -73111.521 | J12: ='The Model'!J243-'The Model'!J214 -> -130526.66
D13: FCF to Equity (NI+Dep-Capex-chge NWC+ Net Debt | F13: =F8+F9+F10+F11 -> 7153.0204 | G13: =G8+G9+G10+G11 -> 13444.415 | H13: =H8+H9+H10+H11 -> 19258.884 | I13: =I8+I9+I10+I11 -> 30732.713 | J13: =J8+J9+J10+J11 -> 56974.031
D14: Terminal Value at end of 2027 (Second Stage, Terminal Value) | J14: =((J13*(1+C5))/(C4-C5)) -> 592104.72
D15: Total FCF to Equity ( both first stage and second stage) | F15: =SUM(F13:F14) -> 7153.0204 | G15: =SUM(G13:G14) -> 13444.415 | H15: =SUM(H13:H14) -> 19258.884 | I15: =SUM(I13:I14) -> 30732.713 | J15: =SUM(J13:J14) -> 649078.75
D16: Total Equity Value | E16: =NPV(C2,F15:J15) -> 378064.96
D17: Total number of Shares Outstanding, in Millions | E17: ='Data Source Table'!H315 -> 4261.515
D18: Per Share | E18: =E16/E17 -> 88.716093
D19: Total FCF to the Firm
D20: After Tax Interest Expense | F20: ='The Model'!F156*(1-'Assumption Table'!$Q$34) -> 497.06404 | G20: ='The Model'!G156*(1-'Assumption Table'!$Q$34) -> 521.91724 | H20: ='The Model'!H156*(1-'Assumption Table'!$Q$34) -> 548.01311 | I20: ='The Model'!I156*(1-'Assumption Table'!$Q$34) -> 575.41376 | J20: ='The Model'!J156*(1-'Assumption Table'!$Q$34) -> 604.18445
D22: Total FCF to the Firm (Total FCF Equity + After tax Interest Expense | F22: =SUM(F8:F11)+F20 -> 7650.0844 | G22: =SUM(G8:G11)+G20 -> 13966.332 | H22: =SUM(H8:H11)+H20 -> 19806.897 | I22: =SUM(I8:I11)+I20 -> 31308.127 | J22: =SUM(J8:J11)+J20 -> 57578.216
D23: Terminal Value at end of 2029 | J23: =((J22*(1+C5))/(C4-C5)) -> 598383.73
D24: Total FCF to the Firm | F24: =SUM(F21:F23) -> 7650.0844 | G24: =SUM(G21:G23) -> 13966.332 | H24: =SUM(H21:H23) -> 19806.897 | I24: =SUM(I21:I23) -> 31308.127 | J24: =SUM(J21:J23) -> 655961.94
D25: Enterprise Value | E25: =NPV(C4,F24:J24) -> 389933.08
D26: Less Total Debt | E26: ='Data Source Table'!H406+'Data Source Table'!H407+'Data Source Table'!H401 -> 17083.538
D27: Total Equity Value | E27: =E25-E26 -> 372849.54
D28: Number of Shares (in millions) | E28: =E17 -> 4261.515
D29: Equity Value Per Share | E29: =E27/E28 -> 87.49225
H31: Sensitivity Analysis of Growth Rate and WACC
E33: =E29 -> 87.49225 | F33: =G33-1% -> 0.02 | G33: =H33-1% -> 0.03 | H33: 0.04 | I33: =H33+1% -> 0.05 | J33: =I33+1% -> 0.06
E34: =E35+2% -> 0.18007181 | F34: 50.008284 | G34: 52.908608 | H34: 56.223051 | I34: 60.047127 | J34: 64.508167
E35: =E36+2% -> 0.16007181 | F35: 60.267926 | G35: 64.362613 | H35: 69.13934 | I35: 74.783996 | J35: 81.556774
E36: 0.14007181 | F36: 74.180275 | G36: 80.231568 | H36: 87.49225 | I36: 96.365132 | J36: 107.45424
E37: =E36-2% -> 0.12007181 | F37: 93.964175 | G37: 103.48797 | H37: 115.39058 | I37: 130.69045 | J37: 151.08418
E38: =E37-2% -> 0.10007181 | F38: 124.05981 | G38: 140.50303 | H38: 162.42078 | I38: 193.09305 | J38: 239.07398

Sheet Capital Structure
A1: FY 2023 (Dec-31-2023) Capital Structure As Reported Details
A2: Description | B2: Type | C2: Principal Due (USD) | D2: Coupon/Base Rate | E2: Weight | F2: Weight * Coupon
A3: 3.000% Senior Notes | B3: Bonds and Notes | C3: 519 | D3: 3.000% | E3: =C3/$C$19 -> 0.030461143 | F3: =E3*D3 -> 0.00091383429
A4: 3.625% Senior Notes | B4: Bonds and Notes | C4: 500 | D4: 3.625% | E4: =C4/$C$19 -> 0.029345995 | F4: =E4*D4 -> 0.0010637923
A5: 3.625% Senior Notes | B5: Bonds and Notes | C5: 1434 | D5: 3.625% | E5: =C5/$C$19 -> 0.084164314 | F5: =E5*D5 -> 0.0030509564
A6: 3.625% Senior Notes | B6: Bonds and Notes | C6: 1215 | D6: 3.625% | E6: =C6/$C$19 -> 0.071310768 | F6: =E6*D6 -> 0.0025850153
A7: 3.875% Senior Notes | B7: Bonds and Notes | C7: 1325 | D7: 3.875% | E7: =C7/$C$19 -> 0.077766887 | F7: =E7*D7 -> 0.0030134669
A8: 4.375% Senior Notes | B8: Bonds and Notes | C8: 1000 | D8: 4.375% | E8: =C8/$C$19 -> 0.05869199 | F8: =E8*D8 -> 0.0025677746
A9: 4.625% Senior Notes | B9: Bonds and Notes | C9: 1215 | D9: 4.625% | E9: =C9/$C$19 -> 0.071310768 | F9: =E9*D9 -> 0.003298123
A10: 4.875% Senior Notes | B10: Bonds and Notes | C10: 1600 | D10: 4.875% | E10: =C10/$C$19 -> 0.093907184 | F10: =E10*D10 -> 0.0045779752
A11: 4.875% Senior Notes | B11: Bonds and Notes | C11: 1000 | D11: 4.875% | E11: =C11/$C$19 -> 0.05869199 | F11: =E11*D11 -> 0.0028612345
A12: 5.375% Senior Notes | B12: Bonds and Notes | C12: 900 | D12: 5.375% | E12: =C12/$C$19 -> 0.052822791 | F12: =E12*D12 -> 0.002839225
A13: 5.750% Senior Notes | B13: Bonds and Notes | C13: 400 | D13: 5.750% | E13: =C13/$C$19 -> 0.023476796 | F13: =E13*D13 -> 0.0013499158
A14: 5.875% Senior Notes | B14: Bonds and Notes | C14: 800 | D14: 5.875% | E14: =C14/$C$19 -> 0.046953592 | F14: =E14*D14 -> 0.0027585235
... A17: Operating Lease Liabilities | B17: Capital Lease | C17: 2430.1 | D17: 3.500% | E17: =C17/$C$19 -> 0.14262741 | F17: =E17*D17 -> 0.0049919592
A18: Unsecured Revolving Credit Facility | B18: Revolving Credit | C18: - | D18: NA
C19: =SUM(C3:C17) -> 17038.1 | E19: Rd | F19: =SUM(F3:F17) -> 0.045416581
G21: BETA | H21: RISK FREE RATE | I21: RISK PREMIUM | J21: COST OF EQUITY
B22: DATE | C22: NETFLIX | D22: S&P 500 | E22: NFLX RETURNS | F22: S&P RETURNS
B23: 44197 | C23: 53.239 | D23: 3714.24 | G23: =SLOPE(E24:E82,F24:F82) -> 1.8444865 | H23: 0.0475 | I23: 0.0525 | J23: =H23+(G23*I23) -> 0.14433554
B24: 44228 | C24: 53.885 | D24: 3811.15 | E24: =LN(C24/C23) -> 0.012060936 | F24: =LN(D24/D23) -> 0.0257569 | H24: As at December 6th | I24: From KPMG
B25: 44256 | C25: 52.166 | D25: 3972.89 | E25: =LN(C25/C24) -> -0.032421204 | F25: =LN(D25/D24) -> 0.041562809
B26: 44287 | C26: 51.347 | D26: 4181.17 | E26: =LN(C26/C25) -> -0.01582443 | F26: =LN(D26/D25) -> 0.051097322
B27: 44317 | C27: 50.281 | D27: 4204.11 | E27: =LN(C27/C26) -> -0.02097924 | F27: =LN(D27/D26) -> 0.0054715066
B28: 44348 | C28: 52.821 | D28: 4297.5 | E28: =LN(C28/C27) -> 0.049281567 | F28: =LN(D28/D27) -> 0.02197084
B29: 44378 | C29: 51.757 | D29: 4395.26 | E29: =LN(C29/C28) -> -0.02034915 | F29: =LN(D29/D28) -> 0.022493229 | G29: MARKET VAL EQUITY | H29: MARKET VALUE OF DEBT | J29: ENTERPRISE VALUE
B30: 44409 | C30: 56.919 | D30: 4522.68 | E30: =LN(C30/C29) -> 0.095069516 | F30: =LN(D30/D29) -> 0.028578051
B31: 44440 | C31: 61.034 | D31: 4307.54 | E31: =LN(C31/C30) -> 0.069801881 | F31: =LN(D31/D30) -> -0.048737763 | G31: ='Data Source Table'!B1109 -> 424749.29 | H31: ='Data Source Table'!B1111 -> 17083.538 | J31: =G31+H31 -> 441832.83
B32: 44470 | C32: 69.031 | D32: 4605.38 | E32: =LN(C32/C31) -> 0.12312459 | F32: =LN(D32/D31) -> 0.06685821
B33: 44501 | C33: 64.19 | D33: 4567 | E33: =LN(C33/C32) -> -0.072708244 | F33: =LN(D33/D32) -> -0.0083686511
B34: 44531 | C34: 60.244 | D34: 4766.18 | E34: =LN(C34/C33) -> -0.063444453 | F34: =LN(D34/D33) -> 0.042688611
B35: 44562 | C35: 42.714 | D35: 4515.55 | E35: =LN(C35/C34) -> -0.34387625 | F35: =LN(D35/D34) -> -0.05401815
B36: 44593 | C36: 39.452 | D36: 4373.94 | E36: =LN(C36/C35) -> -0.079441992 | F36: =LN(D36/D35) -> -0.031862791
B37: 44621 | C37: 37.459 | D37: 4530.41 | E37: =LN(C37/C36) -> -0.051837742 | F37: =LN(D37/D36) -> 0.035148238
B38: 44652 | C38: 19.036 | D38: 4131.93 | E38: =LN(C38/C37) -> -0.67691508 | F38: =LN(D38/D37) -> -0.092067833
B39: 44682 | C39: 19.744 | D39: 4132.15 | E39: =LN(C39/C38) -> 0.036517724 | F39: =LN(D39/D38) -> 5.3242466e-05
B40: 44713 | C40: 17.487 | D40: 3785.38 | E40: =LN(C40/C39) -> -0.1213919 | F40: =LN(D40/D39) -> -0.087651574
B41: 44743 | C41: 22.49 | D41: 4130.29 | E41: =LN(C41/C40) -> 0.25161302 | F41: =LN(D41/D40) -> 0.087201344
B42: 44774 | C42: 22.356 | D42: 3955 | E42: =LN(C42/C41) -> -0.0059760246 | F42: =LN(D42/D41) -> -0.043367021
B43: 44805 | C43: 23.544 | D43: 3585.62 | E43: =LN(C43/C42) -> 0.05177627 | F43: =LN(D43/D42) -> -0.098049199
...

Sheet Data Source Table
A76: DETAILED SEGMENT DATA (in thousands)
A77: Revenue | B77: 2019 | C77: =B77+1 -> 2020 | D77: =C77+1 -> 2021 | E77: =D77+1 -> 2022 | F77: =E77+1 -> 2023 | G77: =F77+1 -> 2024 | I77: 2020 | J77: =I77+1 -> 2021 | K77: =J77+1 -> 2022 | L77: =K77+1 -> 2023 | M77: =L77+1 -> 2024 | O77: Average
A78: UCAN Streaming Revenue | B78: 10051208 | C78: 11455396 | D78: 12972100 | E78: 14084643 | F78: 14873783 | G78: 17359369 | I78: =(C78-B78)/B78 -> 0.13970341 | J78: =(D78-C78)/C78 -> 0.13240084 | K78: =(E78-D78)/D78 -> 0.085764294 | L78: =(F78-E78)/E78 -> 0.056028399 | M78: =(G78-F78)/F78 -> 0.16711189 | O78: =AVERAGE(I78:M78) -> 0.11620177
A79: EMEA Streaming Revenue | B79: 5543067 | C79: 7772252 | D79: 9699819 | E79: 9745015 | F79: 10556487 | G79: 12387035 | I79: =(C79-B79)/B79 -> 0.40215733 | J79: =(D79-C79)/C79 -> 0.24800624 | K79: =(E79-D79)/D79 -> 0.0046594684 | L79: =(F79-E79)/E79 -> 0.083270472 | M79: =(G79-F79)/F79 -> 0.17340504 | O79: =AVERAGE(I79:M79) -> 0.18229971
A80: LATAM Streaming Revenue | B80: 2795434 | C80: 3156727 | D80: 3576976 | E80: 4069973 | F80: 4446461 | G80: 4839816 | I80: =(C80-B80)/B80 -> 0.12924397 | J80: =(D80-C80)/C80 -> 0.13312808 | K80: =(E80-D80)/D80 -> 0.13782508 | L80: =(F80-E80)/E80 -> 0.092503808 | M80: =(G80-F80)/F80 -> 0.088464736 | O80: =AVERAGE(I80:M80) -> 0.11623314
A81: APAC Streaming Revenue | B81: 1469521 | C81: 2372300 | D81: 3266601 | E81: 3570221 | F81: 3763727 | G81: 4414746 | I81: =(C81-B81)/B81 -> 0.61433556 | J81: =(D81-C81)/C81 -> 0.37697635 | K81: =(E81-D81)/D81 -> 0.092946766 | L81: =(F81-E81)/E81 -> 0.054200006 | M81: =(G81-F81)/F81 -> 0.1729719 | O81: =AVERAGE(I81:M81) -> 0.26228612
A82: Total Streaming Revenue | B82: =SUM(B78:B81) -> 19859230 | C82: =SUM(C78:C81) -> 24756675 | D82: =SUM(D78:D81) -> 29515496 | E82: =SUM(E78:E81) -> 31469852 | F82: =SUM(F78:F81) -> 33640458 | G82: =SUM(G78:G81) -> 39000966 | I82: =(C82-B82)/B82 -> 0.246608 | J82: =(D82-C82)/C82 -> 0.19222375 | K82: =(E82-D82)/D82 -> 0.066214574 | L82: =(F82-E82)/E82 -> 0.068974141 | M82: =(G82-F82)/F82 -> 0.15934706 | O82: =AVERAGE(I82:M82) -> 0.14667351
A83: DVD REVENUE | B83: 297217 | C83: 239381 | D83: 182348 | E83: 145698 | F83: 82839 | G83: 0 | I83: =(C83-B83)/B83 -> -0.19459183 | J83: =(D83-C83)/C83 -> -0.23825199 | K83: =(E83-D83)/D83 -> -0.20098932 | L83: =(F83-E83)/E83 -> -0.43143351 | M83: =(G83-F83)/F83 -> -1 | O83: 0 | P83: Because it has been discontinued
A84: Total Revenue | B84: =B83+B82 -> 20156447 | C84: =SUM(C82:C83) -> 24996056 | D84: =SUM(D82:D83) -> 29697844 | E84: =E83+E82 -> 31615550 | F84: =F83+F82 -> 33723297 | G84: =G83+G82 -> 39000966 | I84: =(C84-B84)/B84 -> 0.24010229 | J84: =(D84-C84)/C84 -> 0.18810119 | K84: =(E84-D84)/D84 -> 0.064573913 | L84: =(F84-E84)/E84 -> 0.066668048 | M84: =(G84-F84)/F84 -> 0.1564992 | O84: =AVERAGE(I84:M84) -> 0.14318893
A86: Operating Income | B86: 2604254 | C86: 4585289 | D86: 6194509 | E86: 5632831 | F86: 6954003 | G86: 10417614 | I86: =(C86-B86)/B86 -> 0.76069193 | J86: =(D86-C86)/C86 -> 0.3509528 | K86: =(E86-D86)/D86 -> -0.09067353 | L86: =(F86-E86)/E86 -> 0.23454849 | M86: =(G86-F86)/F86 -> 0.49807442 | O86: =AVERAGE(I86:M86) -> 0.35071882
A87: Operating margin | B87: 0.13 | C87: 0.18 | D87: 0.21 | E87: 0.18 | F87: 0.21 | G87: 0.27 | I87: =(C87-B87)/B87 -> 0.38461538 | J87: =(D87-C87)/C87 -> 0.16666667 | K87: =(E87-D87)/D87 -> -0.14285714 | L87: =(F87-E87)/E87 -> 0.16666667 | M87: =(G87-F87)/F87 -> 0.28571429 | O87: =AVERAGE(I87:M87) -> 0.17216117
A89: Paid net membership additions | B89: 27831 | C89: 36573 | D89: 18181 | E89: 8903 | F89: 29529 | G89: 41350 | I89: =(C89-B89)/B89 -> 0.31411016 | J89: =(D89-C89)/C89 -> -0.50288464 | K89: =(E89-D89)/D89 -> -0.51031296 | L89: =(F89-E89)/E89 -> 2.3167472 | M89: =(G89-F89)/F89 -> 0.40031833 | O89: =AVERAGE(I89:M89) -> 0.40359561
A90: Paid memberships at end of period | B90: 167090 | C90: 203663 | D90: 221844 | E90: 230747 | F90: 260276 | G90: 301626 | I90: =(C90-B90)/B90 -> 0.21888204 | J90: =(D90-C90)/C90 -> 0.08927002 | K90: =(E90-D90)/D90 -> 0.040131804 | L90: =(F90-E90)/E90 -> 0.12797133 | M90: =(G90-F90)/F90 -> 0.15886982 | O90: =AVERAGE(I90:M90) -> 0.127025
A91: Average paying memberships | B91: 152984 | C91: 189083 | D91: 210784 | E91: 222924 | F91: 240889 | G91: 277730 | I91: =(C91-B91)/B91 -> 0.23596585 | J91: =(D91-C91)/C91 -> 0.1147697 | K91: =(E91-D91)/D91 -> 0.057594504 | L91: =(F91-E91)/E91 -> 0.080588003 | M91: =(G91-F91)/F91 -> 0.15293766 | O91: =AVERAGE(I91:M91) -> 0.12837114
A92: Average monthly revenue per paying membership | B92: 10.82 | C92: 10.91 | D92: 11.67 | E92: 11.76 | F92: 11.64 | G92: 11.7 | I92: =(C92-B92)/B92 -> 0.0083179298 | J92: =(D92-C92)/C92 -> 0.069660862 | K92: =(E92-D92)/D92 -> 0.0077120823 | L92: =(F92-E92)/E92 -> -0.010204082 | M92: =(G92-F92)/F92 -> 0.0051546392 | O92: =AVERAGE(I92:M92) -> 0.016128286
A94: Cost of Revenues | B94: 12440213 | C94: 15276319 | D94: 17332683 | E94: 19168285 | F94: 19715368 | G94: 21038464 | I94: =(C94-B94)/B94 -> 0.22797889 | J94: =(D94-C94)/C94 -> 0.13461122 | K94: =(E94-D94)/D94 -> 0.10590409 | L94: =(F94-E94)/E94 -> 0.028541051 | M94: =(G94-F94)/F94 -> 0.067109881 | O94: =AVERAGE(I94:M94) -> 0.11282903
A96: Operating Expense
A97: Sales and Marketing | B97: 2652462 | C97: 2228362 | D97: 2545146 | E97: 2530502 | F97: 2657883 | G97: 2917554 | I97: =(C97-B97)/B97 -> -0.15988919 | J97: =(D97-C97)/C97 -> 0.14216003 | K97: =(E97-D97)/D97 -> -0.0057536974 | L97: =(F97-E97)/E97 -> 0.050338233 | M97: =(G97-F97)/F97 -> 0.097698431 | O97: =AVERAGE(I97:M97) -> 0.024910761
A98: Technology and development | B98: 1545149 | C98: 1829600 | D98: 2273885 | E98: 2711041 | F98: 2675758 | G98: 2925295 | I98: =(C98-B98)/B98 -> 0.18409293 | J98: =(D98-C98)/C98 -> 0.24283177 | K98: =(E98-D98)/D98 -> 0.19225071 | L98: =(F98-E98)/E98 -> -0.013014558 | M98: =(G98-F98)/F98 -> 0.093258434 | O98: =AVERAGE(I98:M98) -> 0.13988386
A99: General and administrative | B99: 914369 | C99: 1076486 | D99: 1351621 | E99: 1572891 | F99: 1720285 | G99: 1702039 | I99: =(C99-B99)/B99 -> 0.17729932 | J99: =(D99-C99)/C99 -> 0.25558623 | K99: =(E99-D99)/D99 -> 0.16370713 | L99: =(F99-E99)/E99 -> 0.093708973 | M99: =(G99-F99)/F99 -> -0.010606382 | O99: =AVERAGE(I99:M99) -> 0.13593905
A100: Interest Expense | B100: 626023 | C100: 767499 | D100: 765620 | E100: 706212 | F100: 699826 | G100: 718733 | I100: =(C100-B100)/B100 -> 0.2259917 | J100: =(D100-C100)/C100 -> -0.0024482117 | K100: =(E100-D100)/D100 -> -0.077594629 | L100: =(F100-E100)/E100 -> -0.0090426104 | M100: =(G100-F100)/F100 -> 0.027016716 | O100: =AVERAGE(I100:M100) -> 0.032784592
A103: CAPITAL EXPENDITURE (in thousands) | B103: 2019 | C103: =B103+1 -> 2020 | D103: =C103+1 -> 2021 | E103: =D103+1 -> 2022 | F103: =E103+1 -> 2023 | G103: =F103+1 -> 2024 | I103: 2020 | J103: =I103+1 -> 2021 | K103: =J103+1 -> 2022 | L103: =K103+1 -> 2023 | M103: =L103+1 -> 2024 | O103: Average
H104: Revenue | I104: =C84 -> 24996056 | J104: =D84 -> 29697844 | K104: =E84 -> 31615550 | L104: =F84 -> 33723297 | M104: =G84 -> 39000966
A106: Land | B106: 6125 | C106: 50700 | D106: 82381 | E106: 85005 | F106: 85000 | G106: 85000 | I106: =C106/$I$104 -> 0.00202832 | J106: =D106/$J$104 -> 0.0027739724 | K106: =E106/$K$104 -> 0.0026887086 | L106: =F106/$L$104 -> 0.0025205127 | M106: =G106/$M$104 -> 0.0021794332 | O106: =AVERAGE(I106:M106) -> 0.0024381894
A107: Building | B107: 33141 | C107: 42717 | D107: 48123 | E107: 52106 | F107: 154165 | G107: 475684 | I107: =C107/$I$104 -> 0.0017089496 | J107: =D107/$J$104 -> 0.0016204207 | K107: =E107/$K$104 -> 0.001648113 | L107: =F107/$L$104 -> 0.0045714688 | M107: =G107/$M$104 -> 0.012196724 | O107: =AVERAGE(I107:M107) -> 0.0043491351
A108: Leasehold improvements | B108: 354999 | C108: 524537 | D108: 863342 | E108: 1040570 | F108: 1032492 | G108: 1026593 | I108: =C108/$I$104 -> 0.020984791 | J108: =D108/$J$104 -> 0.029070865 | K108: =E108/$K$104 -> 0.032913234 | L108: =F108/$L$104 -> 0.030616579 | M108: =G108/$M$104 -> 0.026322245 | O108: =AVERAGE(I108:M108) -> 0.027981543
A109: Furniture and fixtures | B109: 87465 | C109: 110185 | D109: 139809 | E109: 153682 | F109: 144737 | G109: 134987 | I109: =C109/$I$104 -> 0.0044080954 | J109: =D109/$J$104 -> 0.0047077155 | K109: =E109/$K$104 -> 0.0048609624 | L109: =F109/$L$104 -> 0.0042918995 | M109: =G109/$M$104 -> 0.0034611194 | O109: =AVERAGE(I109:M109) -> 0.0043459584
A110: Information technology | B110: 243565 | C110: 283014 | D110: 380452 | E110: 442681 | F110: 414092 | G110: 446419 | I110: =C110/$I$104 -> 0.011322346 | J110: =D110/$J$104 -> 0.012810762 | K110: =E110/$K$104 -> 0.014002002 | L110: =F110/$L$104 -> 0.012279108 | M110: =G110/$M$104 -> 0.011446358 | O110: =AVERAGE(I110:M110) -> 0.012372115
A111: Corporate aircraft | B111: 108995 | C111: 110629 | D111: 110978 | E111: 115578 | F111: 99175 | G111: 99175 | I111: =C111/$I$104 -> 0.0044258582 | J111: =D111/$J$104 -> 0.0037369043 | K111: =E111/$K$104 -> 0.0036557327 | L111: =F111/$L$104 -> 0.0029408453 | M111: =G111/$M$104 -> 0.0025428857 | O111: =AVERAGE(I111:M111) -> 0.0034604452
A112: Machinery and Equipment | B112: 46415 | C112: 34633 | D112: 32426 | E112: 26821 | F112: 10334 | G112: 15135 | I112: =C112/$I$104 -> 0.0013855386 | J112: =D112/$J$104 -> 0.0010918638 | K112: =E112/$K$104 -> 0.00084834836 | L112: =F112/$L$104 -> 0.00030643504 | M112: =G112/$M$104 -> 0.00038806731 | O112: =AVERAGE(I112:M112) -> 0.00080405061
A113: Capital work-in-progress | B113: 100521 | C113: 298558 | D113: 282248 | E113: 235555 | F113: 406492 | G113: 228300 | I113: =C113/$I$104 -> 0.011944204 | J113: =D113/$J$104 -> 0.0095039896 | K113: =E113/$K$104 -> 0.0074506058 | L113: =F113/$L$104 -> 0.012053744 | M113: =G113/$M$104 -> 0.0058537012 | O113: =AVERAGE(I113:M113) -> 0.009361249
A115: WORKING CAPITAL (in millions) | B115: 2019 | C115: =B115+1 -> 2020 | D115: =C115+1 -> 2021 | E115: =D115+1 -> 2022 | F115: =E115+1 -> 2023 | G115: =F115+1 -> 2024 | I115: 2020 | J115: =I115+1 -> 2021 | K115: =J115+1 -> 2022 | L115: =K115+1 -> 2023 | M115: =L115+1 -> 2024 | O115: Average
H116: Revenue | I116: =C84/1000 -> 24996.056 | J116: =D84/1000 -> 29697.844 | K116: =E84/1000 -> 31615.55 | L116: =F84/1000 -> 33723.297 | M116: =G84/1000 -> 39000.966
A118: Accounts Receivable | B118: 454.4 | C118: 610.8 | D118: 804.3 | E118: 988.9 | F118: 1287.1 | G118: 1335.3 | I118: =C118/$I$116 -> 0.024435855 | J118: =D118/$J$116 -> 0.027082774 | K118: =E118/$K$116 -> 0.031278912 | L118: =F118/$L$116 -> 0.038166494 | M118: =G118/$M$116 -> 0.034237613 | O118: =AVERAGE(I118:M118) -> 0.03104033
A119: Other Receivables | B119: - | C119: - | D119: - | E119: 598 | F119: 555 | G119: 653 | I119: =B119 -> - | J119: =C119 -> - | K119: =E119/$K$116 -> 0.018914743 | L119: =F119/$L$116 -> 0.016457466 | M119: =G119/$M$116 -> 0.016743175 | O119: =AVERAGE(I119:M119) -> 0.017371795
A120: Prepaid Exp. | B120: 181 | C120: 203 | D120: 323.8 | E120: 392.7 | F120: 408.9 | G120: 431.9 | I120: =C120/$I$116 -> 0.0081212812 | J120: =D120/$J$116 -> 0.010903148 | K120: =E120/$K$116 -> 0.012421103 | L120: =F120/$L$116 -> 0.012125149 | M120: =G120/$M$116 -> 0.011074085 | O120: =AVERAGE(I120:M120) -> 0.010928953
A121: Other Current Assets | B121: 524.7 | C121: 742.2 | D121: 910.7 | E121: 1225 | F121: 529.3 | G121: 1096.4 | I121: =C121/$I$116 -> 0.029692684 | J121: =D121/$J$116 -> 0.030665526 | K121: =E121/$K$116 -> 0.038746756 | L121: =F121/$L$116 -> 0.015695381 | M121: =G121/$M$116 -> 0.028112124 | O121: =AVERAGE(I121:M121) -> 0.028582494
A123: Accounts Payable | B123: 674.3 | C123: 656.2 | D123: 837.5 | E123: 671.5 | F123: 747.4 | G123: 899.9 | I123: =C123/$I$116 -> 0.026252142 | J123: =D123/$J$116 -> 0.0282007 | K123: =E123/$K$116 -> 0.021239548 | L123: =F123/$L$116 -> 0.02216272 | M123: =G123/$M$116 -> 0.023073787 | O123: =AVERAGE(I123:M123) -> 0.02418578
A124: Accrued Exp. | B124: 652.4 | C124: 846 | D124: 1134.2 | E124: 1158.7 | F124: 1280.6 | G124: 1410.1 | I124: =C124/$I$116 -> 0.033845339 | J124: =D124/$J$116 -> 0.038191325 | K124: =E124/$K$116 -> 0.036649687 | L124: =F124/$L$116 -> 0.037973749 | M124: =G124/$M$116 -> 0.036155515 | O124: =AVERAGE(I124:M124) -> 0.036563123
A125: Curr. Port. of LT Debt | B125: - | C125: 499.9 | D125: 699.8 | E125: - | F125: 399.8 | G125: 1784.5 | I125: =C125/$I$116 -> 0.019999155 | J125: =D125/$J$116 -> 0.023564 | K125: =E125 -> - | L125: =F125/$L$116 -> 0.011855306 | M125: =G125/$M$116 -> 0.045755277 | O125: =AVERAGE(I125:M125) -> 0.025293434
...
